<?xml version="1.0"?>
<robot name="differential_robot" xmlns:xacro="http://www.ros.org/wiki/xacro">

  <!-- ============================================ -->
  <!-- ARQUIVO PRINCIPAL                            -->
  <!-- Importa propriedades e macros, define o robô -->
  <!-- ============================================ -->

  <!-- ==================== -->
  <!-- IMPORTAÇÃO DE ARQUIVOS -->
  <!-- ==================== -->
  <!--
    xacro:include importa o conteúdo de outros arquivos .xacro
    $(find package_name) retorna o caminho do pacote ROS
  -->
  
  <xacro:include filename="$(find rm_description)/urdf/properties.xacro"/>
  <xacro:include filename="$(find rm_description)/urdf/wheels.xacro"/>
  <xacro:include filename="$(find rm_description)/urdf/gazebo_control.xacro"/>
  <xacro:include filename="$(find rm_description)/urdf/sensors.xacro" />
  <xacro:include filename="$(find rm_description)/urdf/inertial_macros.xacro"/>
  <!-- ==================== -->
  <!-- BASE FOOTPRINT       -->
  <!-- ==================== -->
  <link name="base_footprint">
    <inertial>
      <origin xyz="0 0 0"/>
      <mass value="1.0"/>
      <inertia
        ixx="0.1"
        ixy="0.0"
        ixz="0.0"
        iyy="0.1"
        iyz="0.0"
        izz="0.1"/>
    </inertial>
  </link>

  <gazebo reference="base_footprint">
    <gravity>false</gravity>
  </gazebo>
  <!-- ==================== -->
  <!-- BASE LINK            -->
  <!-- ==================== -->
  <link name="base_link">
    <visual>
      <origin xyz="0.13 0 0" rpy="0 0 0"/>
      <geometry>
        <box size="${base_length} ${base_width} ${base_height}"/>
      </geometry>
      <material name="gray"/>
    </visual>
    <collision>
      <origin xyz="0 0 0" rpy="0 0 0"/>
      <geometry>
        <box size="${base_length} ${base_width} ${base_height}"/>
      </geometry>
    </collision>
    <xacro:inertial_box
        mass="${base_mass}"
        x="${base_length}"
        y="${base_width}"
        z="${base_height}">
      <origin xyz="0 0 0"/>
    </xacro:inertial_box>
  </link>

  <joint name="base_joint" type="fixed">
    <parent link="base_footprint"/>
    <child link="base_link"/>
    <origin xyz="0 0 ${0.1 + base_height/2}" rpy="0 0 0"/>
  </joint>
  
  <!-- Roda Esquerda -->
  <xacro:wheels
  name="left_wheel"
  material="blue"/>

  <joint name="left_wheel_joint" type="continuous">
  <parent link="base_link"/>
  <child link="left_wheel"/>
  <origin xyz="0 ${base_width/2 + 0.05/2} 0"
          rpy="1.5708 0 0"/>
  <axis xyz="0 0 1"/>
  </joint>

  <!-- Roda Direita -->
  <xacro:wheels
  name="right_wheel"
  material="blue"/>

  <joint name="right_wheel_joint" type="continuous">
  <parent link="base_link"/>
  <child link="right_wheel"/>
  <origin xyz="0 -${base_width/2 + 0.05/2} 0" rpy="1.5708 0 0"/>
  <axis xyz="0 0 1"/>
</joint>
 
  <xacro:sphere_link
  name="caster_ball"
  radius="0.1"
  mass="1"
  material="red"/>

  <joint name="caster_joint" type="fixed">
  <parent link="base_link"/>
  <child link="caster_ball"/>

  <origin xyz="0.27 0 -0.05"
          rpy="0 0 0"/>
</joint>

<!-- ==================== -->
<!-- CAMERA LINK -->
<!-- ==================== -->

<link name="camera">
  <visual>
    <origin xyz="0 0 0" rpy="0 0 0"/>
    <geometry>
      <box size="0.05 0.05 0.05"/>
    </geometry>
    <material name="green"/>
  </visual>

  <collision>
    <origin xyz="0 0 0" rpy="0 0 0"/>
    <geometry>
      <box size="0.05 0.05 0.05"/>
    </geometry>
  </collision>

  <inertial>
    <origin xyz="0 0 0"/>
    <mass value="0.1"/>
    <inertia
      ixx="0.0001"
      ixy="0.0"
      ixz="0.0"
      iyy="0.0001"
      iyz="0.0"
      izz="0.0001"/>
  </inertial>
</link>

<!-- ==================== -->
<!-- CAMERA JOINT -->
<!-- ==================== -->

<joint name="camera_joint" type="fixed">
  <parent link="base_link"/>
  <child link="camera"/>

  <!-- frente do robô -->
  <origin xyz="-0.15 0 0" rpy="0 0 3.14159"/>
</joint>

<!-- ==================== -->
<!-- IMU LINK -->
<!-- ==================== -->

<link name="IMU">
</link>

<!-- ==================== -->
<!-- IMU JOINT -->
<!-- ==================== --> 

<joint name="imu_joint" type="fixed">
  <parent link="base_link"/>
  <child link="IMU"/>

  <!-- frente do robô -->
  <origin xyz="0 0 0" rpy="0 0 0"/>
</joint>

<!-- ==================== -->
<!-- LIDAR LINK -->
<!-- ==================== -->

<link name="lidar">
  <visual>
    <origin xyz="0 0 0" rpy="0 0 0"/>
    <geometry>
      <!-- cilindro achatado -->
      <cylinder radius="0.06" length="0.02"/>
    </geometry>
    <material name="red"/>
  </visual>

  <collision>
    <origin xyz="0 0 0" rpy="0 0 0"/>
    <geometry>
      <cylinder radius="0.06" length="0.02"/>
    </geometry>
  </collision>

  <inertial>
    <origin xyz="0 0 0"/>
    <mass value="0.1"/>
    <inertia
      ixx="0.0001"
      ixy="0"
      ixz="0"
      iyy="0.0001"
      iyz="0"
      izz="0.0001"/>
  </inertial>
</link>

<!-- ==================== -->
<!-- LIDAR JOINT -->
<!-- ==================== -->

<joint name="lidar_joint" type="fixed">
  <parent link="base_link"/>
  <child link="lidar"/>

  <!-- em cima do robô -->
  <origin xyz="0 0 ${base_height/2 + 0.06}" rpy="0 0 0"/>
</joint>

</robot>

  